2019-02-05 03:34:15 ERROR (Thread-2) [homeassistant.util.yaml] YAML file /home/homeassistant/.homeassistant/emulated_hue.yaml contains duplicate key "light.bed_room". Check lines 27 and 37.
2019-02-05 03:34:15 ERROR (Thread-2) [homeassistant.util.yaml] YAML file /home/homeassistant/.homeassistant/emulated_hue.yaml contains duplicate key "switch.quat_ngu_1". Check lines 15 and 108.
2019-02-05 03:34:15 ERROR (Thread-2) [homeassistant.util.yaml] YAML file /home/homeassistant/.homeassistant/emulated_hue.yaml contains duplicate key "switch.quat_ngu_on_3". Check lines 17 and 110.
2019-02-05 03:34:15 ERROR (Thread-2) [homeassistant.util.yaml] YAML file /home/homeassistant/.homeassistant/emulated_hue.yaml contains duplicate key "switch.tuoi_lan". Check lines 19 and 138.
2019-02-05 03:34:18 WARNING (MainThread) [homeassistant.components.http] legacy_api_password support has been enabled. If you don't require it, remove the 'api_password' from your http config.
2019-02-05 03:34:21 WARNING (Recorder) [homeassistant.components.recorder] Ended unfinished session (id=104 from 2019-02-05 01:33:29.382475)
2019-02-05 03:34:21 WARNING (MainThread) [homeassistant.loader] You are using a custom component for climate.broadlink which has not been tested by Home Assistant. This component might cause stability problems, be sure to disable it if you do experience issues with Home Assistant.
2019-02-05 03:34:21 WARNING (MainThread) [homeassistant.components.emulated_hue] Emulated Hue running in legacy mode because type has been specified. More info at https://goo.gl/M6tgz8
2019-02-05 03:34:21 WARNING (MainThread) [homeassistant.loader] You are using a custom component for device_tracker.icloud2 which has not been tested by Home Assistant. This component might cause stability problems, be sure to disable it if you do experience issues with Home Assistant.
2019-02-05 03:34:22 WARNING (MainThread) [homeassistant.loader] You are using a custom component for weather_forecast which has not been tested by Home Assistant. This component might cause stability problems, be sure to disable it if you do experience issues with Home Assistant.
2019-02-05 03:34:22 WARNING (MainThread) [homeassistant.loader] You are using a custom component for notify.fcm-android which has not been tested by Home Assistant. This component might cause stability problems, be sure to disable it if you do experience issues with Home Assistant.
2019-02-05 03:34:23 WARNING (MainThread) [homeassistant.loader] You are using a custom component for sonoff which has not been tested by Home Assistant. This component might cause stability problems, be sure to disable it if you do experience issues with Home Assistant.
2019-02-05 03:46:57 WARNING (Thread-12) [homeassistant.components.light.flux_led] Failed to connect to bulb 192.168.1.20, flux_lamppost
2019-02-05 03:46:57 ERROR (Thread-15) [pynetgear] Error talking to API
Traceback (most recent call last):
  File "/srv/homeassistant/lib/python3.5/site-packages/urllib3/connection.py", line 159, in _new_conn
    (self._dns_host, self.port), self.timeout, **extra_kw)
  File "/srv/homeassistant/lib/python3.5/site-packages/urllib3/util/connection.py", line 80, in create_connection
    raise err
  File "/srv/homeassistant/lib/python3.5/site-packages/urllib3/util/connection.py", line 70, in create_connection
    sock.connect(sa)
ConnectionRefusedError: [Errno 111] Connection refused

During handling of the above exception, another exception occurred:

Traceback (most recent call last):
  File "/srv/homeassistant/lib/python3.5/site-packages/urllib3/connectionpool.py", line 600, in urlopen
    chunked=chunked)
  File "/srv/homeassistant/lib/python3.5/site-packages/urllib3/connectionpool.py", line 354, in _make_request
    conn.request(method, url, **httplib_request_kw)
  File "/usr/lib/python3.5/http/client.py", line 1107, in request
    self._send_request(method, url, body, headers)
  File "/usr/lib/python3.5/http/client.py", line 1152, in _send_request
    self.endheaders(body)
  File "/usr/lib/python3.5/http/client.py", line 1103, in endheaders
    self._send_output(message_body)
  File "/usr/lib/python3.5/http/client.py", line 934, in _send_output
    self.send(msg)
  File "/usr/lib/python3.5/http/client.py", line 877, in send
    self.connect()
  File "/srv/homeassistant/lib/python3.5/site-packages/urllib3/connection.py", line 181, in connect
    conn = self._new_conn()
  File "/srv/homeassistant/lib/python3.5/site-packages/urllib3/connection.py", line 168, in _new_conn
    self, "Failed to establish a new connection: %s" % e)
urllib3.exceptions.NewConnectionError: <urllib3.connection.HTTPConnection object at 0x6896ca50>: Failed to establish a new connection: [Errno 111] Connection refused

During handling of the above exception, another exception occurred:

Traceback (most recent call last):
  File "/srv/homeassistant/lib/python3.5/site-packages/requests/adapters.py", line 449, in send
    timeout=timeout
  File "/srv/homeassistant/lib/python3.5/site-packages/urllib3/connectionpool.py", line 638, in urlopen
    _stacktrace=sys.exc_info()[2])
  File "/srv/homeassistant/lib/python3.5/site-packages/urllib3/util/retry.py", line 398, in increment
    raise MaxRetryError(_pool, url, error or ResponseError(cause))
urllib3.exceptions.MaxRetryError: HTTPConnectionPool(host='192.168.1.1', port=5000): Max retries exceeded with url: /soap/server_sa/ (Caused by NewConnectionError('<urllib3.connection.HTTPConnection object at 0x6896ca50>: Failed to establish a new connection: [Errno 111] Connection refused',))

During handling of the above exception, another exception occurred:

Traceback (most recent call last):
  File "/srv/homeassistant/lib/python3.5/site-packages/pynetgear/__init__.py", line 373, in _make_request
    data=message, timeout=30, verify=False)
  File "/srv/homeassistant/lib/python3.5/site-packages/requests/api.py", line 116, in post
    return request('post', url, data=data, json=json, **kwargs)
  File "/srv/homeassistant/lib/python3.5/site-packages/requests/api.py", line 60, in request
    return session.request(method=method, url=url, **kwargs)
  File "/srv/homeassistant/lib/python3.5/site-packages/requests/sessions.py", line 533, in request
    resp = self.send(prep, **send_kwargs)
  File "/srv/homeassistant/lib/python3.5/site-packages/requests/sessions.py", line 646, in send
    r = adapter.send(request, **kwargs)
  File "/srv/homeassistant/lib/python3.5/site-packages/requests/adapters.py", line 516, in send
    raise ConnectionError(e, request=request)
requests.exceptions.ConnectionError: HTTPConnectionPool(host='192.168.1.1', port=5000): Max retries exceeded with url: /soap/server_sa/ (Caused by NewConnectionError('<urllib3.connection.HTTPConnection object at 0x6896ca50>: Failed to establish a new connection: [Errno 111] Connection refused',))
2019-02-05 03:46:57 ERROR (Thread-15) [pynetgear] Error talking to API
Traceback (most recent call last):
  File "/srv/homeassistant/lib/python3.5/site-packages/urllib3/connection.py", line 159, in _new_conn
    (self._dns_host, self.port), self.timeout, **extra_kw)
  File "/srv/homeassistant/lib/python3.5/site-packages/urllib3/util/connection.py", line 80, in create_connection
    raise err
  File "/srv/homeassistant/lib/python3.5/site-packages/urllib3/util/connection.py", line 70, in create_connection
    sock.connect(sa)
ConnectionRefusedError: [Errno 111] Connection refused

During handling of the above exception, another exception occurred:

Traceback (most recent call last):
  File "/srv/homeassistant/lib/python3.5/site-packages/urllib3/connectionpool.py", line 600, in urlopen
    chunked=chunked)
  File "/srv/homeassistant/lib/python3.5/site-packages/urllib3/connectionpool.py", line 354, in _make_request
    conn.request(method, url, **httplib_request_kw)
  File "/usr/lib/python3.5/http/client.py", line 1107, in request
    self._send_request(method, url, body, headers)
  File "/usr/lib/python3.5/http/client.py", line 1152, in _send_request
    self.endheaders(body)
  File "/usr/lib/python3.5/http/client.py", line 1103, in endheaders
    self._send_output(message_body)
  File "/usr/lib/python3.5/http/client.py", line 934, in _send_output
    self.send(msg)
  File "/usr/lib/python3.5/http/client.py", line 877, in send
    self.connect()
  File "/srv/homeassistant/lib/python3.5/site-packages/urllib3/connection.py", line 181, in connect
    conn = self._new_conn()
  File "/srv/homeassistant/lib/python3.5/site-packages/urllib3/connection.py", line 168, in _new_conn
    self, "Failed to establish a new connection: %s" % e)
urllib3.exceptions.NewConnectionError: <urllib3.connection.HTTPConnection object at 0x65b409f0>: Failed to establish a new connection: [Errno 111] Connection refused

During handling of the above exception, another exception occurred:

Traceback (most recent call last):
  File "/srv/homeassistant/lib/python3.5/site-packages/requests/adapters.py", line 449, in send
    timeout=timeout
  File "/srv/homeassistant/lib/python3.5/site-packages/urllib3/connectionpool.py", line 638, in urlopen
    _stacktrace=sys.exc_info()[2])
  File "/srv/homeassistant/lib/python3.5/site-packages/urllib3/util/retry.py", line 398, in increment
    raise MaxRetryError(_pool, url, error or ResponseError(cause))
urllib3.exceptions.MaxRetryError: HTTPConnectionPool(host='192.168.1.1', port=5000): Max retries exceeded with url: /soap/server_sa/ (Caused by NewConnectionError('<urllib3.connection.HTTPConnection object at 0x65b409f0>: Failed to establish a new connection: [Errno 111] Connection refused',))

During handling of the above exception, another exception occurred:

Traceback (most recent call last):
  File "/srv/homeassistant/lib/python3.5/site-packages/pynetgear/__init__.py", line 373, in _make_request
    data=message, timeout=30, verify=False)
  File "/srv/homeassistant/lib/python3.5/site-packages/requests/api.py", line 116, in post
    return request('post', url, data=data, json=json, **kwargs)
  File "/srv/homeassistant/lib/python3.5/site-packages/requests/api.py", line 60, in request
    return session.request(method=method, url=url, **kwargs)
  File "/srv/homeassistant/lib/python3.5/site-packages/requests/sessions.py", line 533, in request
    resp = self.send(prep, **send_kwargs)
  File "/srv/homeassistant/lib/python3.5/site-packages/requests/sessions.py", line 646, in send
    r = adapter.send(request, **kwargs)
  File "/srv/homeassistant/lib/python3.5/site-packages/requests/adapters.py", line 516, in send
    raise ConnectionError(e, request=request)
requests.exceptions.ConnectionError: HTTPConnectionPool(host='192.168.1.1', port=5000): Max retries exceeded with url: /soap/server_sa/ (Caused by NewConnectionError('<urllib3.connection.HTTPConnection object at 0x65b409f0>: Failed to establish a new connection: [Errno 111] Connection refused',))
2019-02-05 03:46:57 ERROR (Thread-15) [pynetgear] Get attached devices failed
2019-02-05 03:46:58 ERROR (Thread-15) [homeassistant.components.device_tracker.netgear] Failed to Login
2019-02-05 03:46:58 ERROR (MainThread) [homeassistant.core] Error doing job: Task exception was never retrieved
Traceback (most recent call last):
  File "/usr/lib/python3.5/asyncio/tasks.py", line 239, in _step
    result = coro.send(None)
  File "/srv/homeassistant/lib/python3.5/site-packages/homeassistant/helpers/entity_platform.py", line 344, in _async_add_entity
    raise HomeAssistantError(msg)
homeassistant.exceptions.HomeAssistantError: Entity id already exists: cover.garage_door
2019-02-05 03:46:58 ERROR (MainThread) [homeassistant.components.device_tracker] Error setting up platform netgear
2019-02-05 03:46:58 WARNING (Thread-9) [homeassistant.components.light.flux_led] Failed to connect to bulb 192.168.1.20, led TV
2019-02-05 03:46:59 WARNING (MainThread) [homeassistant.loader] You are using a custom component for switch.sonoff which has not been tested by Home Assistant. This component might cause stability problems, be sure to disable it if you do experience issues with Home Assistant.
2019-02-05 03:47:01 ERROR (Thread-3) [homeassistant.components.light.yeelight] Failed to connect to bulb 192.168.1.19, Bed Room: A socket error occurred when sending the command.
2019-02-05 03:47:06 ERROR (Thread-23) [homeassistant.components.device_tracker.icloud] Multiple devices with name: luongsiphone
2019-02-05 03:47:06 ERROR (Thread-23) [homeassistant.components.device_tracker.icloud] Multiple devices with name: luongsiphone
2019-02-05 03:47:07 ERROR (MainThread) [homeassistant.core] Error doing job: Task exception was never retrieved
Traceback (most recent call last):
  File "/usr/lib/python3.5/asyncio/tasks.py", line 241, in _step
    result = coro.throw(exc)
  File "/srv/homeassistant/lib/python3.5/site-packages/homeassistant/setup.py", line 56, in async_setup_component
    return await task  # type: ignore
  File "/usr/lib/python3.5/asyncio/futures.py", line 380, in __iter__
    yield self  # This tells Task to wait for completion.
  File "/usr/lib/python3.5/asyncio/tasks.py", line 304, in _wakeup
    future.result()
  File "/usr/lib/python3.5/asyncio/futures.py", line 293, in result
    raise self._exception
  File "/usr/lib/python3.5/asyncio/tasks.py", line 241, in _step
    result = coro.throw(exc)
  File "/srv/homeassistant/lib/python3.5/site-packages/homeassistant/setup.py", line 125, in _async_setup_component
    await async_process_deps_reqs(hass, config, domain, component)
  File "/srv/homeassistant/lib/python3.5/site-packages/homeassistant/setup.py", line 239, in async_process_deps_reqs
    hass, config, name, module.DEPENDENCIES)  # type: ignore
  File "/srv/homeassistant/lib/python3.5/site-packages/homeassistant/setup.py", line 78, in _async_process_dependencies
    results = await asyncio.gather(*tasks, loop=hass.loop)
  File "/usr/lib/python3.5/asyncio/futures.py", line 380, in __iter__
    yield self  # This tells Task to wait for completion.
  File "/usr/lib/python3.5/asyncio/tasks.py", line 304, in _wakeup
    future.result()
  File "/usr/lib/python3.5/asyncio/futures.py", line 293, in result
    raise self._exception
  File "/usr/lib/python3.5/asyncio/tasks.py", line 239, in _step
    result = coro.send(None)
  File "/srv/homeassistant/lib/python3.5/site-packages/homeassistant/config_entries.py", line 459, in async_forward_entry_setup
    self.hass, component, self._hass_config)
  File "/srv/homeassistant/lib/python3.5/site-packages/homeassistant/setup.py", line 45, in async_setup_component
    return await setup_tasks[domain]  # type: ignore
  File "/usr/lib/python3.5/asyncio/futures.py", line 382, in __iter__
    return self.result()  # May raise too.
  File "/usr/lib/python3.5/asyncio/futures.py", line 293, in result
    raise self._exception
  File "/usr/lib/python3.5/asyncio/tasks.py", line 239, in _step
    result = coro.send(None)
  File "/srv/homeassistant/lib/python3.5/site-packages/homeassistant/setup.py", line 45, in async_setup_component
    return await setup_tasks[domain]  # type: ignore
  File "/usr/lib/python3.5/asyncio/futures.py", line 382, in __iter__
    return self.result()  # May raise too.
  File "/usr/lib/python3.5/asyncio/futures.py", line 293, in result
    raise self._exception
  File "/usr/lib/python3.5/asyncio/tasks.py", line 241, in _step
    result = coro.throw(exc)
  File "/srv/homeassistant/lib/python3.5/site-packages/homeassistant/setup.py", line 56, in async_setup_component
    return await task  # type: ignore
  File "/usr/lib/python3.5/asyncio/futures.py", line 380, in __iter__
    yield self  # This tells Task to wait for completion.
  File "/usr/lib/python3.5/asyncio/tasks.py", line 304, in _wakeup
    future.result()
  File "/usr/lib/python3.5/asyncio/futures.py", line 293, in result
    raise self._exception
  File "/usr/lib/python3.5/asyncio/tasks.py", line 239, in _step
    result = coro.send(None)
  File "/srv/homeassistant/lib/python3.5/site-packages/homeassistant/setup.py", line 118, in _async_setup_component
    conf_util.async_process_component_config(hass, config, domain)
  File "/srv/homeassistant/lib/python3.5/site-packages/homeassistant/config.py", line 763, in async_process_component_config
    platform = get_platform(hass, domain, p_name)
  File "/srv/homeassistant/lib/python3.5/site-packages/homeassistant/loader.py", line 61, in get_platform
    domain=domain, platform=platform_name))
  File "/srv/homeassistant/lib/python3.5/site-packages/homeassistant/loader.py", line 117, in _load_file
    module = importlib.import_module(path)
  File "/usr/lib/python3.5/importlib/__init__.py", line 126, in import_module
    return _bootstrap._gcd_import(name[level:], package, level)
  File "<frozen importlib._bootstrap>", line 986, in _gcd_import
  File "<frozen importlib._bootstrap>", line 969, in _find_and_load
  File "<frozen importlib._bootstrap>", line 958, in _find_and_load_unlocked
  File "<frozen importlib._bootstrap>", line 673, in _load_unlocked
  File "<frozen importlib._bootstrap_external>", line 669, in exec_module
  File "<frozen importlib._bootstrap_external>", line 775, in get_code
  File "<frozen importlib._bootstrap_external>", line 735, in source_to_code
  File "<frozen importlib._bootstrap>", line 222, in _call_with_frames_removed
  File "/home/homeassistant/.homeassistant/custom_components/media_player/alexa.py", line 1
    Skip to content
          ^
SyntaxError: invalid syntax
2019-02-05 03:47:07 ERROR (MainThread) [homeassistant.core] Error doing job: Task exception was never retrieved
Traceback (most recent call last):
  File "/usr/lib/python3.5/asyncio/tasks.py", line 241, in _step
    result = coro.throw(exc)
  File "/srv/homeassistant/lib/python3.5/site-packages/homeassistant/setup.py", line 56, in async_setup_component
    return await task  # type: ignore
  File "/usr/lib/python3.5/asyncio/futures.py", line 380, in __iter__
    yield self  # This tells Task to wait for completion.
  File "/usr/lib/python3.5/asyncio/tasks.py", line 304, in _wakeup
    future.result()
  File "/usr/lib/python3.5/asyncio/futures.py", line 293, in result
    raise self._exception
  File "/usr/lib/python3.5/asyncio/tasks.py", line 241, in _step
    result = coro.throw(exc)
  File "/srv/homeassistant/lib/python3.5/site-packages/homeassistant/setup.py", line 125, in _async_setup_component
    await async_process_deps_reqs(hass, config, domain, component)
  File "/srv/homeassistant/lib/python3.5/site-packages/homeassistant/setup.py", line 239, in async_process_deps_reqs
    hass, config, name, module.DEPENDENCIES)  # type: ignore
  File "/srv/homeassistant/lib/python3.5/site-packages/homeassistant/setup.py", line 78, in _async_process_dependencies
    results = await asyncio.gather(*tasks, loop=hass.loop)
  File "/usr/lib/python3.5/asyncio/futures.py", line 380, in __iter__
    yield self  # This tells Task to wait for completion.
  File "/usr/lib/python3.5/asyncio/tasks.py", line 304, in _wakeup
    future.result()
  File "/usr/lib/python3.5/asyncio/futures.py", line 293, in result
    raise self._exception
  File "/usr/lib/python3.5/asyncio/tasks.py", line 239, in _step
    result = coro.send(None)
  File "/srv/homeassistant/lib/python3.5/site-packages/homeassistant/config_entries.py", line 459, in async_forward_entry_setup
    self.hass, component, self._hass_config)
  File "/srv/homeassistant/lib/python3.5/site-packages/homeassistant/setup.py", line 45, in async_setup_component
    return await setup_tasks[domain]  # type: ignore
  File "/usr/lib/python3.5/asyncio/futures.py", line 382, in __iter__
    return self.result()  # May raise too.
  File "/usr/lib/python3.5/asyncio/futures.py", line 293, in result
    raise self._exception
  File "/usr/lib/python3.5/asyncio/tasks.py", line 239, in _step
    result = coro.send(None)
  File "/srv/homeassistant/lib/python3.5/site-packages/homeassistant/setup.py", line 45, in async_setup_component
    return await setup_tasks[domain]  # type: ignore
  File "/usr/lib/python3.5/asyncio/futures.py", line 382, in __iter__
    return self.result()  # May raise too.
  File "/usr/lib/python3.5/asyncio/futures.py", line 293, in result
    raise self._exception
  File "/usr/lib/python3.5/asyncio/tasks.py", line 241, in _step
    result = coro.throw(exc)
  File "/srv/homeassistant/lib/python3.5/site-packages/homeassistant/setup.py", line 56, in async_setup_component
    return await task  # type: ignore
  File "/usr/lib/python3.5/asyncio/futures.py", line 380, in __iter__
    yield self  # This tells Task to wait for completion.
  File "/usr/lib/python3.5/asyncio/tasks.py", line 304, in _wakeup
    future.result()
  File "/usr/lib/python3.5/asyncio/futures.py", line 293, in result
    raise self._exception
  File "/usr/lib/python3.5/asyncio/tasks.py", line 239, in _step
    result = coro.send(None)
  File "/srv/homeassistant/lib/python3.5/site-packages/homeassistant/setup.py", line 118, in _async_setup_component
    conf_util.async_process_component_config(hass, config, domain)
  File "/srv/homeassistant/lib/python3.5/site-packages/homeassistant/config.py", line 763, in async_process_component_config
    platform = get_platform(hass, domain, p_name)
  File "/srv/homeassistant/lib/python3.5/site-packages/homeassistant/loader.py", line 61, in get_platform
    domain=domain, platform=platform_name))
  File "/srv/homeassistant/lib/python3.5/site-packages/homeassistant/loader.py", line 117, in _load_file
    module = importlib.import_module(path)
  File "/usr/lib/python3.5/importlib/__init__.py", line 126, in import_module
    return _bootstrap._gcd_import(name[level:], package, level)
  File "<frozen importlib._bootstrap>", line 986, in _gcd_import
  File "<frozen importlib._bootstrap>", line 969, in _find_and_load
  File "<frozen importlib._bootstrap>", line 958, in _find_and_load_unlocked
  File "<frozen importlib._bootstrap>", line 673, in _load_unlocked
  File "<frozen importlib._bootstrap_external>", line 669, in exec_module
  File "<frozen importlib._bootstrap_external>", line 775, in get_code
  File "<frozen importlib._bootstrap_external>", line 735, in source_to_code
  File "<frozen importlib._bootstrap>", line 222, in _call_with_frames_removed
  File "/home/homeassistant/.homeassistant/custom_components/media_player/alexa.py", line 1
    Skip to content
          ^
SyntaxError: invalid syntax
2019-02-05 03:47:07 ERROR (MainThread) [homeassistant.core] Error doing job: Task exception was never retrieved
Traceback (most recent call last):
  File "/usr/lib/python3.5/asyncio/tasks.py", line 241, in _step
    result = coro.throw(exc)
  File "/srv/homeassistant/lib/python3.5/site-packages/homeassistant/setup.py", line 56, in async_setup_component
    return await task  # type: ignore
  File "/usr/lib/python3.5/asyncio/futures.py", line 380, in __iter__
    yield self  # This tells Task to wait for completion.
  File "/usr/lib/python3.5/asyncio/tasks.py", line 304, in _wakeup
    future.result()
  File "/usr/lib/python3.5/asyncio/futures.py", line 293, in result
    raise self._exception
  File "/usr/lib/python3.5/asyncio/tasks.py", line 241, in _step
    result = coro.throw(exc)
  File "/srv/homeassistant/lib/python3.5/site-packages/homeassistant/setup.py", line 125, in _async_setup_component
    await async_process_deps_reqs(hass, config, domain, component)
  File "/srv/homeassistant/lib/python3.5/site-packages/homeassistant/setup.py", line 239, in async_process_deps_reqs
    hass, config, name, module.DEPENDENCIES)  # type: ignore
  File "/srv/homeassistant/lib/python3.5/site-packages/homeassistant/setup.py", line 78, in _async_process_dependencies
    results = await asyncio.gather(*tasks, loop=hass.loop)
  File "/usr/lib/python3.5/asyncio/futures.py", line 380, in __iter__
    yield self  # This tells Task to wait for completion.
  File "/usr/lib/python3.5/asyncio/tasks.py", line 304, in _wakeup
    future.result()
  File "/usr/lib/python3.5/asyncio/futures.py", line 293, in result
    raise self._exception
  File "/usr/lib/python3.5/asyncio/tasks.py", line 239, in _step
    result = coro.send(None)
  File "/srv/homeassistant/lib/python3.5/site-packages/homeassistant/config_entries.py", line 459, in async_forward_entry_setup
    self.hass, component, self._hass_config)
  File "/srv/homeassistant/lib/python3.5/site-packages/homeassistant/setup.py", line 45, in async_setup_component
    return await setup_tasks[domain]  # type: ignore
  File "/usr/lib/python3.5/asyncio/futures.py", line 382, in __iter__
    return self.result()  # May raise too.
  File "/usr/lib/python3.5/asyncio/futures.py", line 293, in result
    raise self._exception
  File "/usr/lib/python3.5/asyncio/tasks.py", line 239, in _step
    result = coro.send(None)
  File "/srv/homeassistant/lib/python3.5/site-packages/homeassistant/setup.py", line 45, in async_setup_component
    return await setup_tasks[domain]  # type: ignore
  File "/usr/lib/python3.5/asyncio/futures.py", line 382, in __iter__
    return self.result()  # May raise too.
  File "/usr/lib/python3.5/asyncio/futures.py", line 293, in result
    raise self._exception
  File "/usr/lib/python3.5/asyncio/tasks.py", line 241, in _step
    result = coro.throw(exc)
  File "/srv/homeassistant/lib/python3.5/site-packages/homeassistant/setup.py", line 56, in async_setup_component
    return await task  # type: ignore
  File "/usr/lib/python3.5/asyncio/futures.py", line 380, in __iter__
    yield self  # This tells Task to wait for completion.
  File "/usr/lib/python3.5/asyncio/tasks.py", line 304, in _wakeup
    future.result()
  File "/usr/lib/python3.5/asyncio/futures.py", line 293, in result
    raise self._exception
  File "/usr/lib/python3.5/asyncio/tasks.py", line 239, in _step
    result = coro.send(None)
  File "/srv/homeassistant/lib/python3.5/site-packages/homeassistant/setup.py", line 118, in _async_setup_component
    conf_util.async_process_component_config(hass, config, domain)
  File "/srv/homeassistant/lib/python3.5/site-packages/homeassistant/config.py", line 763, in async_process_component_config
    platform = get_platform(hass, domain, p_name)
  File "/srv/homeassistant/lib/python3.5/site-packages/homeassistant/loader.py", line 61, in get_platform
    domain=domain, platform=platform_name))
  File "/srv/homeassistant/lib/python3.5/site-packages/homeassistant/loader.py", line 117, in _load_file
    module = importlib.import_module(path)
  File "/usr/lib/python3.5/importlib/__init__.py", line 126, in import_module
    return _bootstrap._gcd_import(name[level:], package, level)
  File "<frozen importlib._bootstrap>", line 986, in _gcd_import
  File "<frozen importlib._bootstrap>", line 969, in _find_and_load
  File "<frozen importlib._bootstrap>", line 958, in _find_and_load_unlocked
  File "<frozen importlib._bootstrap>", line 673, in _load_unlocked
  File "<frozen importlib._bootstrap_external>", line 669, in exec_module
  File "<frozen importlib._bootstrap_external>", line 775, in get_code
  File "<frozen importlib._bootstrap_external>", line 735, in source_to_code
  File "<frozen importlib._bootstrap>", line 222, in _call_with_frames_removed
  File "/home/homeassistant/.homeassistant/custom_components/media_player/alexa.py", line 1
    Skip to content
          ^
SyntaxError: invalid syntax
2019-02-05 03:47:07 ERROR (Recorder) [homeassistant.components.recorder.util] Error executing query: (sqlite3.DatabaseError) database disk image is malformed [SQL: 'INSERT INTO events (event_type, event_data, origin, time_fired, created, context_id, context_user_id) VALUES (?, ?, ?, ?, ?, ?, ?)'] [parameters: ('service_registered', '{"domain": "recorder", "service": "purge"}', 'LOCAL', '2019-02-05 03:34:18.265148', '2019-02-05 03:47:07.415327', '46d6704ac4464a8c94a395f258390891', None)] (Background on this error at: http://sqlalche.me/e/4xp6)
2019-02-05 03:47:07 WARNING (Thread-19) [homeassistant.components.homekit] You have exceeded the device limit, which might cause issues. Consider using the filter option.
2019-02-05 05:14:13 ERROR (MainThread) [homeassistant.components.automation] Error while executing automation automation.notify_mo_tv. Invalid data for call_service at pos 2: required key not provided @ data['message']
2019-02-05 05:14:39 ERROR (MainThread) [homeassistant.components.automation] Error while executing automation automation.notify_mo_tv. Invalid data for call_service at pos 2: required key not provided @ data['message']
2019-02-05 05:15:51 ERROR (MainThread) [homeassistant.components.emulated_hue.hue_api] Entity not found: group.livingroom_fan
2019-02-05 05:36:42 ERROR (MainThread) [homeassistant.components.websocket_api.http.connection.1612487280] Client exceeded max pending messages [2]: 512
2019-02-05 05:36:42 ERROR (MainThread) [homeassistant.components.websocket_api.http.connection.1612487280] Client exceeded max pending messages [2]: 512
2019-02-05 05:36:42 ERROR (MainThread) [homeassistant.components.websocket_api.http.connection.1612487280] Client exceeded max pending messages [2]: 512
2019-02-05 05:36:42 ERROR (MainThread) [homeassistant.components.websocket_api.http.connection.1612487280] Client exceeded max pending messages [2]: 512
2019-02-05 05:36:42 ERROR (MainThread) [homeassistant.components.websocket_api.http.connection.1612487280] Client exceeded max pending messages [2]: 512
2019-02-05 05:41:57 ERROR (Thread-2) [homeassistant.components.recorder.util] Error executing query: Couldn't parse datetime string: '\x00\x00\x00\x00\x00\x00\x00\x00\x00\x00\x00\x00\x00\x00\x00\x00\x00\x00\x00\x00\x00\x00\x00\x00\x00\x00'
2019-02-05 05:41:57 ERROR (MainThread) [aiohttp.server] Error handling request
Traceback (most recent call last):
  File "/srv/homeassistant/lib/python3.5/site-packages/aiohttp/web_protocol.py", line 418, in start
    resp = await task
  File "/usr/lib/python3.5/asyncio/futures.py", line 380, in __iter__
    yield self  # This tells Task to wait for completion.
  File "/usr/lib/python3.5/asyncio/tasks.py", line 304, in _wakeup
    future.result()
  File "/usr/lib/python3.5/asyncio/futures.py", line 293, in result
    raise self._exception
  File "/usr/lib/python3.5/asyncio/tasks.py", line 241, in _step
    result = coro.throw(exc)
  File "/srv/homeassistant/lib/python3.5/site-packages/aiohttp/web_app.py", line 458, in _handle
    resp = await handler(request)
  File "/srv/homeassistant/lib/python3.5/site-packages/aiohttp/web_middlewares.py", line 119, in impl
    return await handler(request)
  File "/srv/homeassistant/lib/python3.5/site-packages/homeassistant/components/http/static.py", line 66, in staticresource_middleware
    return await handler(request)
  File "/srv/homeassistant/lib/python3.5/site-packages/homeassistant/components/http/real_ip.py", line 34, in real_ip_middleware
    return await handler(request)
  File "/srv/homeassistant/lib/python3.5/site-packages/homeassistant/components/http/ban.py", line 67, in ban_middleware
    return await handler(request)
  File "/srv/homeassistant/lib/python3.5/site-packages/homeassistant/components/http/auth.py", line 99, in auth_middleware
    return await handler(request)
  File "/srv/homeassistant/lib/python3.5/site-packages/homeassistant/components/http/view.py", line 118, in handle
    result = await result
  File "/srv/homeassistant/lib/python3.5/site-packages/homeassistant/components/history.py", line 318, in get
    entity_ids, self.filters, include_start_time_state)
  File "/usr/lib/python3.5/asyncio/futures.py", line 380, in __iter__
    yield self  # This tells Task to wait for completion.
  File "/usr/lib/python3.5/asyncio/tasks.py", line 304, in _wakeup
    future.result()
  File "/usr/lib/python3.5/asyncio/futures.py", line 293, in result
    raise self._exception
  File "/usr/lib/python3.5/concurrent/futures/thread.py", line 55, in run
    result = self.fn(*self.args, **self.kwargs)
  File "/srv/homeassistant/lib/python3.5/site-packages/homeassistant/components/history.py", line 79, in get_significant_states
    include_start_time_state)
  File "/srv/homeassistant/lib/python3.5/site-packages/homeassistant/components/history.py", line 225, in states_to_json
    for state in get_states(hass, start_time, entity_ids, filters=filters):
  File "/srv/homeassistant/lib/python3.5/site-packages/homeassistant/components/history.py", line 200, in get_states
    return [state for state in execute(query)
  File "/srv/homeassistant/lib/python3.5/site-packages/homeassistant/components/recorder/util.py", line 64, in execute
    (row.to_native() for row in qry)
  File "/srv/homeassistant/lib/python3.5/site-packages/homeassistant/components/recorder/util.py", line 63, in <listcomp>
    row for row in
  File "/srv/homeassistant/lib/python3.5/site-packages/homeassistant/components/recorder/util.py", line 64, in <genexpr>
    (row.to_native() for row in qry)
  File "/srv/homeassistant/lib/python3.5/site-packages/sqlalchemy/orm/loading.py", line 98, in instances
    util.raise_from_cause(err)
  File "/srv/homeassistant/lib/python3.5/site-packages/sqlalchemy/util/compat.py", line 265, in raise_from_cause
    reraise(type(exception), exception, tb=exc_tb, cause=cause)
  File "/srv/homeassistant/lib/python3.5/site-packages/sqlalchemy/util/compat.py", line 249, in reraise
    raise value
  File "/srv/homeassistant/lib/python3.5/site-packages/sqlalchemy/orm/loading.py", line 79, in instances
    rows = [proc(row) for row in fetch]
  File "/srv/homeassistant/lib/python3.5/site-packages/sqlalchemy/orm/loading.py", line 79, in <listcomp>
    rows = [proc(row) for row in fetch]
  File "/srv/homeassistant/lib/python3.5/site-packages/sqlalchemy/orm/loading.py", line 511, in _instance
    loaded_instance, populate_existing, populators)
  File "/srv/homeassistant/lib/python3.5/site-packages/sqlalchemy/orm/loading.py", line 611, in _populate_full
    dict_[key] = getter(row)
ValueError: Couldn't parse datetime string: '\x00\x00\x00\x00\x00\x00\x00\x00\x00\x00\x00\x00\x00\x00\x00\x00\x00\x00\x00\x00\x00\x00\x00\x00\x00\x00'
2019-02-05 05:41:59 ERROR (Thread-14) [homeassistant.components.recorder.util] Error executing query: Couldn't parse datetime string: '\x00\x00\x00\x00\x00\x00\x00\x00\x00\x00\x00\x00\x00\x00\x00\x00\x00\x00\x00\x00\x00\x00\x00\x00\x00\x00'
2019-02-05 05:41:59 ERROR (MainThread) [aiohttp.server] Error handling request
Traceback (most recent call last):
  File "/srv/homeassistant/lib/python3.5/site-packages/aiohttp/web_protocol.py", line 418, in start
    resp = await task
  File "/usr/lib/python3.5/asyncio/futures.py", line 380, in __iter__
    yield self  # This tells Task to wait for completion.
  File "/usr/lib/python3.5/asyncio/tasks.py", line 304, in _wakeup
    future.result()
  File "/usr/lib/python3.5/asyncio/futures.py", line 293, in result
    raise self._exception
  File "/usr/lib/python3.5/asyncio/tasks.py", line 241, in _step
    result = coro.throw(exc)
  File "/srv/homeassistant/lib/python3.5/site-packages/aiohttp/web_app.py", line 458, in _handle
    resp = await handler(request)
  File "/srv/homeassistant/lib/python3.5/site-packages/aiohttp/web_middlewares.py", line 119, in impl
    return await handler(request)
  File "/srv/homeassistant/lib/python3.5/site-packages/homeassistant/components/http/static.py", line 66, in staticresource_middleware
    return await handler(request)
  File "/srv/homeassistant/lib/python3.5/site-packages/homeassistant/components/http/real_ip.py", line 34, in real_ip_middleware
    return await handler(request)
  File "/srv/homeassistant/lib/python3.5/site-packages/homeassistant/components/http/ban.py", line 67, in ban_middleware
    return await handler(request)
  File "/srv/homeassistant/lib/python3.5/site-packages/homeassistant/components/http/auth.py", line 99, in auth_middleware
    return await handler(request)
  File "/srv/homeassistant/lib/python3.5/site-packages/homeassistant/components/http/view.py", line 118, in handle
    result = await result
  File "/srv/homeassistant/lib/python3.5/site-packages/homeassistant/components/history.py", line 318, in get
    entity_ids, self.filters, include_start_time_state)
  File "/usr/lib/python3.5/asyncio/futures.py", line 380, in __iter__
    yield self  # This tells Task to wait for completion.
  File "/usr/lib/python3.5/asyncio/tasks.py", line 304, in _wakeup
    future.result()
  File "/usr/lib/python3.5/asyncio/futures.py", line 293, in result
    raise self._exception
  File "/usr/lib/python3.5/concurrent/futures/thread.py", line 55, in run
    result = self.fn(*self.args, **self.kwargs)
  File "/srv/homeassistant/lib/python3.5/site-packages/homeassistant/components/history.py", line 79, in get_significant_states
    include_start_time_state)
  File "/srv/homeassistant/lib/python3.5/site-packages/homeassistant/components/history.py", line 225, in states_to_json
    for state in get_states(hass, start_time, entity_ids, filters=filters):
  File "/srv/homeassistant/lib/python3.5/site-packages/homeassistant/components/history.py", line 200, in get_states
    return [state for state in execute(query)
  File "/srv/homeassistant/lib/python3.5/site-packages/homeassistant/components/recorder/util.py", line 64, in execute
    (row.to_native() for row in qry)
  File "/srv/homeassistant/lib/python3.5/site-packages/homeassistant/components/recorder/util.py", line 63, in <listcomp>
    row for row in
  File "/srv/homeassistant/lib/python3.5/site-packages/homeassistant/components/recorder/util.py", line 64, in <genexpr>
    (row.to_native() for row in qry)
  File "/srv/homeassistant/lib/python3.5/site-packages/sqlalchemy/orm/loading.py", line 98, in instances
    util.raise_from_cause(err)
  File "/srv/homeassistant/lib/python3.5/site-packages/sqlalchemy/util/compat.py", line 265, in raise_from_cause
    reraise(type(exception), exception, tb=exc_tb, cause=cause)
  File "/srv/homeassistant/lib/python3.5/site-packages/sqlalchemy/util/compat.py", line 249, in reraise
    raise value
  File "/srv/homeassistant/lib/python3.5/site-packages/sqlalchemy/orm/loading.py", line 79, in instances
    rows = [proc(row) for row in fetch]
  File "/srv/homeassistant/lib/python3.5/site-packages/sqlalchemy/orm/loading.py", line 79, in <listcomp>
    rows = [proc(row) for row in fetch]
  File "/srv/homeassistant/lib/python3.5/site-packages/sqlalchemy/orm/loading.py", line 511, in _instance
    loaded_instance, populate_existing, populators)
  File "/srv/homeassistant/lib/python3.5/site-packages/sqlalchemy/orm/loading.py", line 611, in _populate_full
    dict_[key] = getter(row)
ValueError: Couldn't parse datetime string: '\x00\x00\x00\x00\x00\x00\x00\x00\x00\x00\x00\x00\x00\x00\x00\x00\x00\x00\x00\x00\x00\x00\x00\x00\x00\x00'
2019-02-05 05:42:00 ERROR (Thread-16) [homeassistant.components.recorder.util] Error executing query: Couldn't parse datetime string: '\x00\x00\x00\x00\x00\x00\x00\x00\x00\x00\x00\x00\x00\x00\x00\x00\x00\x00\x00\x00\x00\x00\x00\x00\x00\x00'
2019-02-05 05:42:00 ERROR (MainThread) [aiohttp.server] Error handling request
Traceback (most recent call last):
  File "/srv/homeassistant/lib/python3.5/site-packages/aiohttp/web_protocol.py", line 418, in start
    resp = await task
  File "/usr/lib/python3.5/asyncio/futures.py", line 380, in __iter__
    yield self  # This tells Task to wait for completion.
  File "/usr/lib/python3.5/asyncio/tasks.py", line 304, in _wakeup
    future.result()
  File "/usr/lib/python3.5/asyncio/futures.py", line 293, in result
    raise self._exception
  File "/usr/lib/python3.5/asyncio/tasks.py", line 241, in _step
    result = coro.throw(exc)
  File "/srv/homeassistant/lib/python3.5/site-packages/aiohttp/web_app.py", line 458, in _handle
    resp = await handler(request)
  File "/srv/homeassistant/lib/python3.5/site-packages/aiohttp/web_middlewares.py", line 119, in impl
    return await handler(request)
  File "/srv/homeassistant/lib/python3.5/site-packages/homeassistant/components/http/static.py", line 66, in staticresource_middleware
    return await handler(request)
  File "/srv/homeassistant/lib/python3.5/site-packages/homeassistant/components/http/real_ip.py", line 34, in real_ip_middleware
    return await handler(request)
  File "/srv/homeassistant/lib/python3.5/site-packages/homeassistant/components/http/ban.py", line 67, in ban_middleware
    return await handler(request)
  File "/srv/homeassistant/lib/python3.5/site-packages/homeassistant/components/http/auth.py", line 99, in auth_middleware
    return await handler(request)
  File "/srv/homeassistant/lib/python3.5/site-packages/homeassistant/components/http/view.py", line 118, in handle
    result = await result
  File "/srv/homeassistant/lib/python3.5/site-packages/homeassistant/components/history.py", line 318, in get
    entity_ids, self.filters, include_start_time_state)
  File "/usr/lib/python3.5/asyncio/futures.py", line 380, in __iter__
    yield self  # This tells Task to wait for completion.
  File "/usr/lib/python3.5/asyncio/tasks.py", line 304, in _wakeup
    future.result()
  File "/usr/lib/python3.5/asyncio/futures.py", line 293, in result
    raise self._exception
  File "/usr/lib/python3.5/concurrent/futures/thread.py", line 55, in run
    result = self.fn(*self.args, **self.kwargs)
  File "/srv/homeassistant/lib/python3.5/site-packages/homeassistant/components/history.py", line 79, in get_significant_states
    include_start_time_state)
  File "/srv/homeassistant/lib/python3.5/site-packages/homeassistant/components/history.py", line 225, in states_to_json
    for state in get_states(hass, start_time, entity_ids, filters=filters):
  File "/srv/homeassistant/lib/python3.5/site-packages/homeassistant/components/history.py", line 200, in get_states
    return [state for state in execute(query)
  File "/srv/homeassistant/lib/python3.5/site-packages/homeassistant/components/recorder/util.py", line 64, in execute
    (row.to_native() for row in qry)
  File "/srv/homeassistant/lib/python3.5/site-packages/homeassistant/components/recorder/util.py", line 63, in <listcomp>
    row for row in
  File "/srv/homeassistant/lib/python3.5/site-packages/homeassistant/components/recorder/util.py", line 64, in <genexpr>
    (row.to_native() for row in qry)
  File "/srv/homeassistant/lib/python3.5/site-packages/sqlalchemy/orm/loading.py", line 98, in instances
    util.raise_from_cause(err)
  File "/srv/homeassistant/lib/python3.5/site-packages/sqlalchemy/util/compat.py", line 265, in raise_from_cause
    reraise(type(exception), exception, tb=exc_tb, cause=cause)
  File "/srv/homeassistant/lib/python3.5/site-packages/sqlalchemy/util/compat.py", line 249, in reraise
    raise value
  File "/srv/homeassistant/lib/python3.5/site-packages/sqlalchemy/orm/loading.py", line 79, in instances
    rows = [proc(row) for row in fetch]
  File "/srv/homeassistant/lib/python3.5/site-packages/sqlalchemy/orm/loading.py", line 79, in <listcomp>
    rows = [proc(row) for row in fetch]
  File "/srv/homeassistant/lib/python3.5/site-packages/sqlalchemy/orm/loading.py", line 511, in _instance
    loaded_instance, populate_existing, populators)
  File "/srv/homeassistant/lib/python3.5/site-packages/sqlalchemy/orm/loading.py", line 611, in _populate_full
    dict_[key] = getter(row)
ValueError: Couldn't parse datetime string: '\x00\x00\x00\x00\x00\x00\x00\x00\x00\x00\x00\x00\x00\x00\x00\x00\x00\x00\x00\x00\x00\x00\x00\x00\x00\x00'
2019-02-05 05:42:56 ERROR (MainThread) [homeassistant.core] Error doing job: Fatal read error on socket transport
Traceback (most recent call last):
  File "/usr/lib/python3.5/asyncio/selector_events.py", line 723, in _read_ready
    data = self._sock.recv(self.max_size)
OSError: [Errno 113] No route to host
2019-02-05 07:00:21 WARNING (MainThread) [homeassistant.helpers.entity] Update of switch.original_xiaomi_mi_smart_wifi_socket is taking over 10 seconds
