2018-12-09 16:46:20 WARNING (MainThread) [homeassistant.components.http] legacy_api_password support has been enabled. If you don't require it, remove the 'api_password' from your http config.
2018-12-09 16:46:24 WARNING (MainThread) [homeassistant.loader] You are using a custom component for climate.broadlink which has not been tested by Home Assistant. This component might cause stability problems, be sure to disable it if you do experience issues with Home Assistant.
2018-12-09 16:46:24 WARNING (MainThread) [homeassistant.loader] You are using a custom component for device_tracker.icloud2 which has not been tested by Home Assistant. This component might cause stability problems, be sure to disable it if you do experience issues with Home Assistant.
2018-12-09 16:46:25 WARNING (MainThread) [homeassistant.components.emulated_hue] Emulated Hue running in legacy mode because type has been specified. More info at https://goo.gl/M6tgz8
2018-12-09 16:46:26 ERROR (SyncWorker_19) [pynetgear] Error talking to API
Traceback (most recent call last):
  File "/usr/local/lib/python3.6/site-packages/urllib3/connection.py", line 159, in _new_conn
    (self._dns_host, self.port), self.timeout, **extra_kw)
  File "/usr/local/lib/python3.6/site-packages/urllib3/util/connection.py", line 80, in create_connection
    raise err
  File "/usr/local/lib/python3.6/site-packages/urllib3/util/connection.py", line 70, in create_connection
    sock.connect(sa)
ConnectionRefusedError: [Errno 111] Connection refused

During handling of the above exception, another exception occurred:

Traceback (most recent call last):
  File "/usr/local/lib/python3.6/site-packages/urllib3/connectionpool.py", line 600, in urlopen
    chunked=chunked)
  File "/usr/local/lib/python3.6/site-packages/urllib3/connectionpool.py", line 354, in _make_request
    conn.request(method, url, **httplib_request_kw)
  File "/usr/local/lib/python3.6/http/client.py", line 1239, in request
    self._send_request(method, url, body, headers, encode_chunked)
  File "/usr/local/lib/python3.6/http/client.py", line 1285, in _send_request
    self.endheaders(body, encode_chunked=encode_chunked)
  File "/usr/local/lib/python3.6/http/client.py", line 1234, in endheaders
    self._send_output(message_body, encode_chunked=encode_chunked)
  File "/usr/local/lib/python3.6/http/client.py", line 1026, in _send_output
    self.send(msg)
  File "/usr/local/lib/python3.6/http/client.py", line 964, in send
    self.connect()
  File "/usr/local/lib/python3.6/site-packages/urllib3/connection.py", line 181, in connect
    conn = self._new_conn()
  File "/usr/local/lib/python3.6/site-packages/urllib3/connection.py", line 168, in _new_conn
    self, "Failed to establish a new connection: %s" % e)
urllib3.exceptions.NewConnectionError: <urllib3.connection.HTTPConnection object at 0x705dcd30>: Failed to establish a new connection: [Errno 111] Connection refused

During handling of the above exception, another exception occurred:

Traceback (most recent call last):
  File "/usr/local/lib/python3.6/site-packages/requests/adapters.py", line 449, in send
    timeout=timeout
  File "/usr/local/lib/python3.6/site-packages/urllib3/connectionpool.py", line 638, in urlopen
    _stacktrace=sys.exc_info()[2])
  File "/usr/local/lib/python3.6/site-packages/urllib3/util/retry.py", line 398, in increment
    raise MaxRetryError(_pool, url, error or ResponseError(cause))
urllib3.exceptions.MaxRetryError: HTTPConnectionPool(host='192.168.1.1', port=5000): Max retries exceeded with url: /soap/server_sa/ (Caused by NewConnectionError('<urllib3.connection.HTTPConnection object at 0x705dcd30>: Failed to establish a new connection: [Errno 111] Connection refused',))

During handling of the above exception, another exception occurred:

Traceback (most recent call last):
  File "/usr/local/lib/python3.6/site-packages/pynetgear/__init__.py", line 373, in _make_request
    data=message, timeout=30, verify=False)
  File "/usr/local/lib/python3.6/site-packages/requests/api.py", line 116, in post
    return request('post', url, data=data, json=json, **kwargs)
  File "/usr/local/lib/python3.6/site-packages/requests/api.py", line 60, in request
    return session.request(method=method, url=url, **kwargs)
  File "/usr/local/lib/python3.6/site-packages/requests/sessions.py", line 533, in request
    resp = self.send(prep, **send_kwargs)
  File "/usr/local/lib/python3.6/site-packages/requests/sessions.py", line 646, in send
    r = adapter.send(request, **kwargs)
  File "/usr/local/lib/python3.6/site-packages/requests/adapters.py", line 516, in send
    raise ConnectionError(e, request=request)
requests.exceptions.ConnectionError: HTTPConnectionPool(host='192.168.1.1', port=5000): Max retries exceeded with url: /soap/server_sa/ (Caused by NewConnectionError('<urllib3.connection.HTTPConnection object at 0x705dcd30>: Failed to establish a new connection: [Errno 111] Connection refused',))
2018-12-09 16:46:26 ERROR (SyncWorker_19) [pynetgear] Error talking to API
Traceback (most recent call last):
  File "/usr/local/lib/python3.6/site-packages/urllib3/connection.py", line 159, in _new_conn
    (self._dns_host, self.port), self.timeout, **extra_kw)
  File "/usr/local/lib/python3.6/site-packages/urllib3/util/connection.py", line 80, in create_connection
    raise err
  File "/usr/local/lib/python3.6/site-packages/urllib3/util/connection.py", line 70, in create_connection
    sock.connect(sa)
ConnectionRefusedError: [Errno 111] Connection refused

During handling of the above exception, another exception occurred:

Traceback (most recent call last):
  File "/usr/local/lib/python3.6/site-packages/urllib3/connectionpool.py", line 600, in urlopen
    chunked=chunked)
  File "/usr/local/lib/python3.6/site-packages/urllib3/connectionpool.py", line 354, in _make_request
    conn.request(method, url, **httplib_request_kw)
  File "/usr/local/lib/python3.6/http/client.py", line 1239, in request
    self._send_request(method, url, body, headers, encode_chunked)
  File "/usr/local/lib/python3.6/http/client.py", line 1285, in _send_request
    self.endheaders(body, encode_chunked=encode_chunked)
  File "/usr/local/lib/python3.6/http/client.py", line 1234, in endheaders
    self._send_output(message_body, encode_chunked=encode_chunked)
  File "/usr/local/lib/python3.6/http/client.py", line 1026, in _send_output
    self.send(msg)
  File "/usr/local/lib/python3.6/http/client.py", line 964, in send
    self.connect()
  File "/usr/local/lib/python3.6/site-packages/urllib3/connection.py", line 181, in connect
    conn = self._new_conn()
  File "/usr/local/lib/python3.6/site-packages/urllib3/connection.py", line 168, in _new_conn
    self, "Failed to establish a new connection: %s" % e)
urllib3.exceptions.NewConnectionError: <urllib3.connection.HTTPConnection object at 0x705aac70>: Failed to establish a new connection: [Errno 111] Connection refused

During handling of the above exception, another exception occurred:

Traceback (most recent call last):
  File "/usr/local/lib/python3.6/site-packages/requests/adapters.py", line 449, in send
    timeout=timeout
  File "/usr/local/lib/python3.6/site-packages/urllib3/connectionpool.py", line 638, in urlopen
    _stacktrace=sys.exc_info()[2])
  File "/usr/local/lib/python3.6/site-packages/urllib3/util/retry.py", line 398, in increment
    raise MaxRetryError(_pool, url, error or ResponseError(cause))
urllib3.exceptions.MaxRetryError: HTTPConnectionPool(host='192.168.1.1', port=5000): Max retries exceeded with url: /soap/server_sa/ (Caused by NewConnectionError('<urllib3.connection.HTTPConnection object at 0x705aac70>: Failed to establish a new connection: [Errno 111] Connection refused',))

During handling of the above exception, another exception occurred:

Traceback (most recent call last):
  File "/usr/local/lib/python3.6/site-packages/pynetgear/__init__.py", line 373, in _make_request
    data=message, timeout=30, verify=False)
  File "/usr/local/lib/python3.6/site-packages/requests/api.py", line 116, in post
    return request('post', url, data=data, json=json, **kwargs)
  File "/usr/local/lib/python3.6/site-packages/requests/api.py", line 60, in request
    return session.request(method=method, url=url, **kwargs)
  File "/usr/local/lib/python3.6/site-packages/requests/sessions.py", line 533, in request
    resp = self.send(prep, **send_kwargs)
  File "/usr/local/lib/python3.6/site-packages/requests/sessions.py", line 646, in send
    r = adapter.send(request, **kwargs)
  File "/usr/local/lib/python3.6/site-packages/requests/adapters.py", line 516, in send
    raise ConnectionError(e, request=request)
requests.exceptions.ConnectionError: HTTPConnectionPool(host='192.168.1.1', port=5000): Max retries exceeded with url: /soap/server_sa/ (Caused by NewConnectionError('<urllib3.connection.HTTPConnection object at 0x705aac70>: Failed to establish a new connection: [Errno 111] Connection refused',))
2018-12-09 16:46:26 ERROR (SyncWorker_19) [pynetgear] Get attached devices failed
2018-12-09 16:46:27 ERROR (SyncWorker_19) [homeassistant.components.device_tracker.netgear] Failed to Login
2018-12-09 16:46:27 ERROR (MainThread) [homeassistant.core] Error doing job: Task exception was never retrieved
Traceback (most recent call last):
  File "/usr/local/lib/python3.6/site-packages/homeassistant/helpers/entity_platform.py", line 343, in _async_add_entity
    raise HomeAssistantError(msg)
homeassistant.exceptions.HomeAssistantError: Entity id already exists: cover.garage_door
2018-12-09 16:46:27 ERROR (MainThread) [homeassistant.components.device_tracker] Error setting up platform netgear
2018-12-09 16:46:30 ERROR (SyncWorker_15) [homeassistant.components.light.yeelight] Failed to connect to bulb 192.168.1.9, Bed Room: A socket error occurred when sending the command.
2018-12-09 16:46:31 ERROR (MainThread) [homeassistant.components.sensor.yr] Retrying in 16 minutes: Cannot connect to host aa015h6buqvih86i1.api.met.no:443 ssl:None [Try again]
2018-12-09 16:46:34 ERROR (SyncWorker_17) [homeassistant.components.device_tracker.icloud] Multiple devices with name: luongsiphone
2018-12-09 16:46:34 ERROR (SyncWorker_17) [homeassistant.components.device_tracker.icloud] Multiple devices with name: luongsiphone
2018-12-09 16:46:36 WARNING (SyncWorker_1) [homeassistant.components.light.flux_led] Failed to connect to bulb 192.168.1.20, led TV
2018-12-09 16:46:36 WARNING (MainThread) [homeassistant.components.light] Setup of platform flux_led is taking over 10 seconds.
2018-12-09 16:46:45 WARNING (SyncWorker_14) [homeassistant.components.light.flux_led] Failed to connect to bulb 192.168.1.20, flux_lamppost
2018-12-09 16:46:45 WARNING (MainThread) [homeassistant.core] Unable to find service hassio/addon_restart
2018-12-09 16:50:50 WARNING (MainThread) [homeassistant.core] Unable to find service media_player/volume_set
2018-12-09 16:50:54 WARNING (MainThread) [homeassistant.core] Unable to find service media_player/volume_set
2018-12-09 16:50:55 WARNING (MainThread) [homeassistant.core] Unable to find service media_player/volume_set
2018-12-09 16:50:56 WARNING (MainThread) [homeassistant.core] Unable to find service media_player/volume_set
2018-12-09 16:50:56 WARNING (MainThread) [homeassistant.core] Unable to find service media_player/volume_set
2018-12-09 16:51:02 WARNING (MainThread) [homeassistant.core] Unable to find service media_player/play_media
2018-12-09 16:51:04 WARNING (MainThread) [homeassistant.core] Unable to find service media_player/play_media
2018-12-09 16:51:05 WARNING (MainThread) [homeassistant.core] Unable to find service media_player/play_media
2018-12-09 16:51:06 WARNING (MainThread) [homeassistant.core] Unable to find service media_player/play_media
2018-12-09 16:51:06 WARNING (MainThread) [homeassistant.core] Unable to find service media_player/play_media
2018-12-09 16:51:09 WARNING (MainThread) [homeassistant.core] Unable to find service media_player/volume_set
2018-12-09 16:51:19 WARNING (MainThread) [homeassistant.core] Unable to find service media_player/play_media
